<?xml version="1.0" ?>
<robot name="robot_urd" xmlns:xacro="http://www.ros.org/wiki/xacro">

<xacro:include filename="$(find robot_urd_description)/urdf/materials.xacro" />
<xacro:include filename="$(find robot_urd_description)/urdf/robot_urd.trans" />
<xacro:include filename="$(find robot_urd_description)/urdf/robot_urd.gazebo" />
<link name="base_link">
  <inertial>
    <origin xyz="0.06302135621902447 -0.001654303303745368 0.26447733595472356" rpy="0 0 0"/>
    <mass value="0.8825876155637866"/>
    <inertia ixx="0.002729" iyy="0.001002" izz="0.002223" ixy="-3e-06" iyz="-4.5e-05" ixz="9.3e-05"/>
  </inertial>
  <visual>
    <origin xyz="0 0 0" rpy="0 0 0"/>
    <geometry>
      <mesh filename="package://robot_urd_description/meshes/base_link.stl" scale="0.001 0.001 0.001"/>
    </geometry>
    <material name="silver"/>
  </visual>
  <collision>
    <origin xyz="0 0 0" rpy="0 0 0"/>
    <geometry>
      <mesh filename="package://robot_urd_description/meshes/base_link.stl" scale="0.001 0.001 0.001"/>
    </geometry>
  </collision>
</link>

<link name="lidar_1">
  <inertial>
    <origin xyz="-1.3506771797955341e-06 -5.748661631606658e-05 0.0015504335164893135" rpy="0 0 0"/>
    <mass value="0.003984887751598981"/>
    <inertia ixx="0.0" iyy="0.0" izz="0.0" ixy="0.0" iyz="-0.0" ixz="-0.0"/>
  </inertial>
  <visual>
    <origin xyz="-0.061274 0.004181 -0.336022" rpy="0 0 0"/>
    <geometry>
      <mesh filename="package://robot_urd_description/meshes/lidar_1.stl" scale="0.001 0.001 0.001"/>
    </geometry>
    <material name="silver"/>
  </visual>
  <collision>
    <origin xyz="-0.061274 0.004181 -0.336022" rpy="0 0 0"/>
    <geometry>
      <mesh filename="package://robot_urd_description/meshes/lidar_1.stl" scale="0.001 0.001 0.001"/>
    </geometry>
  </collision>
</link>

<link name="head_1">
  <inertial>
    <origin xyz="-1.59672157926255e-05 -0.0004380575565104748 0.01197783415502518" rpy="0 0 0"/>
    <mass value="0.09646075336203239"/>
    <inertia ixx="1e-05" iyy="7e-06" izz="1e-05" ixy="-0.0" iyz="-0.0" ixz="0.0"/>
  </inertial>
  <visual>
    <origin xyz="-0.0616 0.003419 -0.312367" rpy="0 0 0"/>
    <geometry>
      <mesh filename="package://robot_urd_description/meshes/head_1.stl" scale="0.001 0.001 0.001"/>
    </geometry>
    <material name="silver"/>
  </visual>
  <collision>
    <origin xyz="-0.0616 0.003419 -0.312367" rpy="0 0 0"/>
    <geometry>
      <mesh filename="package://robot_urd_description/meshes/head_1.stl" scale="0.001 0.001 0.001"/>
    </geometry>
  </collision>
</link>

<link name="imu_1">
  <inertial>
    <origin xyz="0.0008064627033654431 -9.300821719877166e-05 0.0025287835840761552" rpy="0 0 0"/>
    <mass value="0.04827749999999997"/>
    <inertia ixx="1e-05" iyy="3e-06" izz="1.2e-05" ixy="0.0" iyz="-0.0" ixz="-0.0"/>
  </inertial>
  <visual>
    <origin xyz="-0.069374 0.001578 -0.262406" rpy="0 0 0"/>
    <geometry>
      <mesh filename="package://robot_urd_description/meshes/imu_1.stl" scale="0.001 0.001 0.001"/>
    </geometry>
    <material name="silver"/>
  </visual>
  <collision>
    <origin xyz="-0.069374 0.001578 -0.262406" rpy="0 0 0"/>
    <geometry>
      <mesh filename="package://robot_urd_description/meshes/imu_1.stl" scale="0.001 0.001 0.001"/>
    </geometry>
  </collision>
</link>

<link name="left_pelvis_1">
  <inertial>
    <origin xyz="0.01795751005501258 0.00014168014442148685 -0.024981592738119313" rpy="0 0 0"/>
    <mass value="0.5234143660816903"/>
    <inertia ixx="0.00028" iyy="0.00028" izz="7.6e-05" ixy="-0.0" iyz="1e-06" ixz="1e-06"/>
  </inertial>
  <visual>
    <origin xyz="-0.050144 -0.059262 -0.240709" rpy="0 0 0"/>
    <geometry>
      <mesh filename="package://robot_urd_description/meshes/left_pelvis_1.stl" scale="0.001 0.001 0.001"/>
    </geometry>
    <material name="silver"/>
  </visual>
  <collision>
    <origin xyz="-0.050144 -0.059262 -0.240709" rpy="0 0 0"/>
    <geometry>
      <mesh filename="package://robot_urd_description/meshes/left_pelvis_1.stl" scale="0.001 0.001 0.001"/>
    </geometry>
  </collision>
</link>

<link name="right_pelvis_1">
  <inertial>
    <origin xyz="0.01795699759739125 0.00011312298216949179 -0.024981817255673278" rpy="0 0 0"/>
    <mass value="0.5234143660816912"/>
    <inertia ixx="0.00028" iyy="0.00028" izz="7.6e-05" ixy="-0.0" iyz="1e-06" ixz="1e-06"/>
  </inertial>
  <visual>
    <origin xyz="-0.050147 0.060657 -0.236291" rpy="0 0 0"/>
    <geometry>
      <mesh filename="package://robot_urd_description/meshes/right_pelvis_1.stl" scale="0.001 0.001 0.001"/>
    </geometry>
    <material name="silver"/>
  </visual>
  <collision>
    <origin xyz="-0.050147 0.060657 -0.236291" rpy="0 0 0"/>
    <geometry>
      <mesh filename="package://robot_urd_description/meshes/right_pelvis_1.stl" scale="0.001 0.001 0.001"/>
    </geometry>
  </collision>
</link>

<link name="right_tight_1">
  <inertial>
    <origin xyz="1.3131126348805977e-05 -0.0031878102092162824 -0.0315229550344438" rpy="0 0 0"/>
    <mass value="0.06375845443348595"/>
    <inertia ixx="4.1e-05" iyy="4.6e-05" izz="4e-06" ixy="-0.0" iyz="0.0" ixz="0.0"/>
  </inertial>
  <visual>
    <origin xyz="-0.068177 0.078327 -0.18818" rpy="0 0 0"/>
    <geometry>
      <mesh filename="package://robot_urd_description/meshes/right_tight_1.stl" scale="0.001 0.001 0.001"/>
    </geometry>
    <material name="silver"/>
  </visual>
  <collision>
    <origin xyz="-0.068177 0.078327 -0.18818" rpy="0 0 0"/>
    <geometry>
      <mesh filename="package://robot_urd_description/meshes/right_tight_1.stl" scale="0.001 0.001 0.001"/>
    </geometry>
  </collision>
</link>

<link name="right_knee_1">
  <inertial>
    <origin xyz="-7.702639705647885e-07 0.01571586630320984 0.000655329465449217" rpy="0 0 0"/>
    <mass value="0.386658515888616"/>
    <inertia ixx="0.000204" iyy="0.000189" izz="6.9e-05" ixy="0.0" iyz="-3.6e-05" ixz="0.0"/>
  </inertial>
  <visual>
    <origin xyz="-0.068216 0.077896 -0.125181" rpy="0 0 0"/>
    <geometry>
      <mesh filename="package://robot_urd_description/meshes/right_knee_1.stl" scale="0.001 0.001 0.001"/>
    </geometry>
    <material name="silver"/>
  </visual>
  <collision>
    <origin xyz="-0.068216 0.077896 -0.125181" rpy="0 0 0"/>
    <geometry>
      <mesh filename="package://robot_urd_description/meshes/right_knee_1.stl" scale="0.001 0.001 0.001"/>
    </geometry>
  </collision>
</link>

<link name="right_ankle_1">
  <inertial>
    <origin xyz="0.0021982763757750212 0.01788953828995568 0.0046541659224381" rpy="0 0 0"/>
    <mass value="0.38668550638021726"/>
    <inertia ixx="0.00019" iyy="0.000202" izz="7e-05" ixy="-0.0" iyz="1e-06" ixz="3.6e-05"/>
  </inertial>
  <visual>
    <origin xyz="-0.068251 0.077505 -0.068183" rpy="0 0 0"/>
    <geometry>
      <mesh filename="package://robot_urd_description/meshes/right_ankle_1.stl" scale="0.001 0.001 0.001"/>
    </geometry>
    <material name="silver"/>
  </visual>
  <collision>
    <origin xyz="-0.068251 0.077505 -0.068183" rpy="0 0 0"/>
    <geometry>
      <mesh filename="package://robot_urd_description/meshes/right_ankle_1.stl" scale="0.001 0.001 0.001"/>
    </geometry>
  </collision>
</link>

<link name="right_foot_1">
  <inertial>
    <origin xyz="-0.017024280857820984 0.0011175257093816726 -0.002681142128240008" rpy="0 0 0"/>
    <mass value="0.5246231337400495"/>
    <inertia ixx="0.000231" iyy="0.00041" izz="0.000365" ixy="-1e-06" iyz="9e-06" ixz="7e-06"/>
  </inertial>
  <visual>
    <origin xyz="-0.086284 0.059142 -0.015318" rpy="0 0 0"/>
    <geometry>
      <mesh filename="package://robot_urd_description/meshes/right_foot_1.stl" scale="0.001 0.001 0.001"/>
    </geometry>
    <material name="silver"/>
  </visual>
  <collision>
    <origin xyz="-0.086284 0.059142 -0.015318" rpy="0 0 0"/>
    <geometry>
      <mesh filename="package://robot_urd_description/meshes/right_foot_1.stl" scale="0.001 0.001 0.001"/>
    </geometry>
  </collision>
</link>

<link name="left_tight_1">
  <inertial>
    <origin xyz="-0.002151588340230909 0.003508611690805394 -0.031415461868238376" rpy="0 0 0"/>
    <mass value="0.0637584544337173"/>
    <inertia ixx="4.1e-05" iyy="4.6e-05" izz="5e-06" ixy="0.0" iyz="0.0" ixz="-2e-06"/>
  </inertial>
  <visual>
    <origin xyz="-0.068174 -0.077422 -0.192781" rpy="0 0 0"/>
    <geometry>
      <mesh filename="package://robot_urd_description/meshes/left_tight_1.stl" scale="0.001 0.001 0.001"/>
    </geometry>
    <material name="silver"/>
  </visual>
  <collision>
    <origin xyz="-0.068174 -0.077422 -0.192781" rpy="0 0 0"/>
    <geometry>
      <mesh filename="package://robot_urd_description/meshes/left_tight_1.stl" scale="0.001 0.001 0.001"/>
    </geometry>
  </collision>
</link>

<link name="left_knee_1">
  <inertial>
    <origin xyz="3.6978467971585105e-05 -0.01572099317087619 0.0004937283037185491" rpy="0 0 0"/>
    <mass value="0.386658515888616"/>
    <inertia ixx="0.000203" iyy="0.000188" izz="7e-05" ixy="3e-06" iyz="3.7e-05" ixz="-9e-06"/>
  </inertial>
  <visual>
    <origin xyz="-0.063883 -0.077632 -0.129927" rpy="0 0 0"/>
    <geometry>
      <mesh filename="package://robot_urd_description/meshes/left_knee_1.stl" scale="0.001 0.001 0.001"/>
    </geometry>
    <material name="silver"/>
  </visual>
  <collision>
    <origin xyz="-0.063883 -0.077632 -0.129927" rpy="0 0 0"/>
    <geometry>
      <mesh filename="package://robot_urd_description/meshes/left_knee_1.stl" scale="0.001 0.001 0.001"/>
    </geometry>
  </collision>
</link>

<link name="left_ankle_1">
  <inertial>
    <origin xyz="0.0022012220104688923 -0.017936491479911477 0.004470456835236988" rpy="0 0 0"/>
    <mass value="0.38668550972567756"/>
    <inertia ixx="0.00019" iyy="0.000202" izz="7e-05" ixy="-0.0" iyz="1e-06" ixz="3.6e-05"/>
  </inertial>
  <visual>
    <origin xyz="-0.06 -0.077823 -0.07306" rpy="0 0 0"/>
    <geometry>
      <mesh filename="package://robot_urd_description/meshes/left_ankle_1.stl" scale="0.001 0.001 0.001"/>
    </geometry>
    <material name="silver"/>
  </visual>
  <collision>
    <origin xyz="-0.06 -0.077823 -0.07306" rpy="0 0 0"/>
    <geometry>
      <mesh filename="package://robot_urd_description/meshes/left_ankle_1.stl" scale="0.001 0.001 0.001"/>
    </geometry>
  </collision>
</link>

<link name="left_foot_1">
  <inertial>
    <origin xyz="-0.017025617718688837 -0.00109945180645684 -0.0026785348014080473" rpy="0 0 0"/>
    <mass value="0.5246231337400495"/>
    <inertia ixx="0.000231" iyy="0.00041" izz="0.000365" ixy="1e-06" iyz="-9e-06" ixz="8e-06"/>
  </inertial>
  <visual>
    <origin xyz="-0.078 -0.06 -0.02" rpy="0 0 0"/>
    <geometry>
      <mesh filename="package://robot_urd_description/meshes/left_foot_1.stl" scale="0.001 0.001 0.001"/>
    </geometry>
    <material name="silver"/>
  </visual>
  <collision>
    <origin xyz="-0.078 -0.06 -0.02" rpy="0 0 0"/>
    <geometry>
      <mesh filename="package://robot_urd_description/meshes/left_foot_1.stl" scale="0.001 0.001 0.001"/>
    </geometry>
  </collision>
</link>

<joint name="Rigid 1" type="fixed">
  <origin xyz="-0.000326 -0.000762 0.023655" rpy="0 0 0"/>
  <parent link="head_1"/>
  <child link="lidar_1"/>
</joint>

<joint name="Revolute 2" type="continuous">
  <origin xyz="0.0616 -0.003419 0.312367" rpy="0 0 0"/>
  <parent link="base_link"/>
  <child link="head_1"/>
  <axis xyz="-0.000619 -0.036817 0.999322"/>
</joint>

<joint name="Rigid 3" type="fixed">
  <origin xyz="0.069374 -0.001578 0.262406" rpy="0 0 0"/>
  <parent link="base_link"/>
  <child link="imu_1"/>
</joint>

<joint name="Revolute 4" type="continuous">
  <origin xyz="0.050144 0.059262 0.240709" rpy="0 0 0"/>
  <parent link="base_link"/>
  <child link="left_pelvis_1"/>
  <axis xyz="1.0 -2e-06 0.000619"/>
</joint>

<joint name="Revolute 5" type="continuous">
  <origin xyz="0.050147 -0.060657 0.236291" rpy="0 0 0"/>
  <parent link="base_link"/>
  <child link="right_pelvis_1"/>
  <axis xyz="1.0 -2e-06 0.000619"/>
</joint>

<joint name="Revolute 6" type="continuous">
  <origin xyz="0.01803 -0.01767 -0.048111" rpy="0 0 0"/>
  <parent link="right_pelvis_1"/>
  <child link="right_tight_1"/>
  <axis xyz="2e-06 -0.999977 -0.006853"/>
</joint>

<joint name="Revolute 7" type="continuous">
  <origin xyz="3.9e-05 0.000431 -0.062999" rpy="0 0 0"/>
  <parent link="right_tight_1"/>
  <child link="right_knee_1"/>
  <axis xyz="-2e-06 0.999977 0.006853"/>
</joint>

<joint name="Revolute 8" type="continuous">
  <origin xyz="3.5e-05 0.000391 -0.056998" rpy="0 0 0"/>
  <parent link="right_knee_1"/>
  <child link="right_ankle_1"/>
  <axis xyz="-2e-06 0.999977 0.006853"/>
</joint>

<joint name="Revolute 9" type="continuous">
  <origin xyz="0.018033 0.018363 -0.052865" rpy="0 0 0"/>
  <parent link="right_ankle_1"/>
  <child link="right_foot_1"/>
  <axis xyz="-1.0 2e-06 -0.000619"/>
</joint>

<joint name="Revolute 10" type="continuous">
  <origin xyz="0.01803 0.01816 -0.047928" rpy="0 0 0"/>
  <parent link="left_pelvis_1"/>
  <child link="left_tight_1"/>
  <axis xyz="0.0 0.999994 0.003345"/>
</joint>

<joint name="Revolute 11" type="continuous">
  <origin xyz="-0.004291 0.00021 -0.062854" rpy="0 0 0"/>
  <parent link="left_tight_1"/>
  <child link="left_knee_1"/>
  <axis xyz="-0.0 -0.999994 -0.003345"/>
</joint>

<joint name="Revolute 12" type="continuous">
  <origin xyz="-0.003883 0.000191 -0.056867" rpy="0 0 0"/>
  <parent link="left_knee_1"/>
  <child link="left_ankle_1"/>
  <axis xyz="0.0 -0.999994 -0.003345"/>
</joint>

<joint name="Revolute 13" type="continuous">
  <origin xyz="0.018 -0.017823 -0.05306" rpy="0 0 0"/>
  <parent link="left_ankle_1"/>
  <child link="left_foot_1"/>
  <axis xyz="-1.0 -0.0 0.0"/>
</joint>

</robot>
